이 에러는 로컬 저장소와 원격 저장소(GitHub)의 히스토리가 달라서 발생하는 문제입니다. 주로 원격 저장소에 있는 변경사항을 로컬에 적용하지 않은 상태에서 push를 시도할 때 발생합니다.

해결 방법은 다음과 같습니다:

1. 먼저 원격 저장소의 변경사항을 가져오기:
```bash
git pull origin main
```

2. 만약 위 명령어로도 해결되지 않는다면, 강제로 원격 저장소의 내용을 가져오기:
```bash
git fetch origin
git reset --hard origin/main
```

3. 그래도 해결되지 않는다면, 변경사항을 강제로 푸시(주의: 기존 원격 저장소의 내용이 덮어써질 수 있음):
```bash
git push -f origin main
```

추천하는 해결 순서:
1. 먼저 `git pull`을 시도해보세요.
2. 충돌이 발생하면 충돌을 해결한 후 다시 커밋하고 푸시하세요.
3. 위 방법들로 해결되지 않을 경우에만 강제 푸시를 고려하세요.

주의: 강제 푸시(`git push -f`)는 원격 저장소의 내용을 완전히 덮어쓸 수 있으므로, 팀 프로젝트에서는 사용하지 않는 것이 좋습니다. 혼자 사용하는 저장소라면 문제없습니다.

이 중에서 어떤 방법을 시도해보셨나요?


